<mujoco model="ability_hand">
  <compiler angle="radian" meshdir="./" autolimits="true"/>
  <default/>
  <asset>
    <mesh name="wristmesh" file="wristmesh.STL"/>
    <mesh name="FB_palm_ref_MIR" file="FB_palm_ref_MIR.STL"/>
    <mesh name="idx-F1" file="idx-F1.STL"/>
    <mesh name="idx-F2" file="idx-F2.STL"/>
    <mesh name="thumb-F1-MIR" file="thumb-F1-MIR.STL"/>
    <mesh name="thumb-F2" file="thumb-F2.STL"/>
  </asset>
  
  <worldbody>
    <light diffuse=".5 .5 .5" pos="0 0 3" dir="0 0 -1"/>
    <geom type="plane" size="1 1 0.1" rgba=".9 0 0 1"/>
  
    <body name="wand" pos="0 0 0.05" gravcomp="0">
      <joint name="wand_joint" type="free"/>
      <geom name="wand_geom" type="cylinder" size="0.02 0.05" mass="0.6"/>
    </body>
 
    <body name="hand" pos="0 0 0.1" gravcomp="0">
      <joint name="base_joint" type="free"/>
      <geom name="wrist_mesh" type="mesh" mass="0.01591" mesh="wristmesh"/>
      <geom name="palm_mesh" pos="-0.0240477 0.00378125 0.0323296" quat="0.0442297 0.00061027 -0.999021 -2.70192e-05" type="mesh" mass="0.26" mesh="FB_palm_ref_MIR"/>
      <body name="index_L1" pos="-0.0279216 -0.00927034 0.0958706" quat="0.685906 0.0469401 -0.714459 -0.129917" gravcomp="0">
        <joint name="index_q1" pos="0 0 0" axis="0 0 1" range="0 2.0944" damping="0.001" frictionloss="0.001"/>
        <geom name="index_mesh_1" pos="0.0384727 0.0032577 0" quat="0.999108 0 0 0.0422244" type="mesh" mass="0.00635888" mesh="idx-F1"/>
        <body name="index_L2" pos="0.0384727 0.0032577 0" quat="0.999108 0 0 0.0422244" gravcomp="0">
          <joint name="index_q2" pos="0 0 0" axis="0 0 1" range="0 2.6586" damping="0.001" frictionloss="0.001"/>
          <geom name="index_mesh_2" pos="0.0091241 0 0" type="mesh" mass="0.00645" mesh="idx-F2"/>
        </body>
      </body>
      <body name="middle_L1" pos="-0.00841718 -0.0115172 0.0990634" quat="0.704562 0.0715738 -0.698395 -0.103508" gravcomp="0">
        <joint name="middle_q1" pos="0 0 0" axis="0 0 1" range="0 2.0944" damping="0.001" frictionloss="0.001"/>
        <geom name="middle_mesh_1" pos="0.0384727 0.0032577 0" quat="0.999108 0 0 0.0422244" type="mesh" mass="0.00635888" mesh="idx-F1"/>
        <body name="middle_L2" pos="0.0384727 0.0032577 0" quat="0.999108 0 0 0.0422244" gravcomp="0">
          <joint name="middle_q2" pos="0 0 0" axis="0 0 1" range="0 2.6586" damping="0.001" frictionloss="0.001"/>
          <geom name="middle_mesh_2" pos="0.0091241 0 0" type="mesh" mass="0.00645" mesh="idx-F2"/>
        </body>
      </body>
      <body name="ring_L1" pos="0.0117529 -0.0103946 0.0967038" quat="0.721351 0.0986547 -0.681173 -0.0769649" gravcomp="0">
        <joint name="ring_q1" pos="0 0 0" axis="0 0 1" range="0 2.0944" damping="0.001" frictionloss="0.001"/>
        <geom name="ring_mesh_1" pos="0.0384727 0.0032577 0" quat="0.999108 0 0 0.0422244" type="mesh" mass="0.00635888" mesh="idx-F1"/>
        <body name="ring_L2" pos="0.0384727 0.0032577 0" quat="0.999108 0 0 0.0422244" gravcomp="0">
          <joint name="ring_q2" pos="0 0 0" axis="0 0 1" range="0 2.6586" damping="0.001" frictionloss="0.001"/>
          <geom name="ring_mesh_2" pos="0.0091241 0 0" type="mesh" mass="0.00645" mesh="idx-F2"/>
        </body>
      </body>
      <body name="pinky_L1" pos="0.0308633 -0.00716283 0.0907346" quat="0.719226 0.122363 -0.681748 -0.0544096" gravcomp="0">
        <joint name="pinky_q1" pos="0 0 0" axis="0 0 1" range="0 2.0944" damping="0.001" frictionloss="0.001"/>
        <geom name="pinky_mesh_1" pos="0.0384727 0.0032577 0" quat="0.999108 0 0 0.0422244" type="mesh" mass="0.00635888" mesh="idx-F1"/>
        <body name="pinky_L2" pos="0.0384727 0.0032577 0" quat="0.999108 0 0 0.0422244" gravcomp="0">
          <joint name="pinky_q2" pos="0 0 0" axis="0 0 1" range="0 2.6586" damping="0.001" frictionloss="0.001"/>
          <geom name="pinky_mesh_2" pos="0.0091241 0 0" type="mesh" mass="0.00645" mesh="idx-F2"/>
        </body>
      </body>
      <body name="thumb_L1" pos="-0.0240477 0.00378125 0.0323296" quat="-0.0947972 0.0440301 -0.00419696 0.994514" gravcomp="0">
        <joint name="thumb_q1" pos="0 0 0" axis="0 0 1" range="-2.0944 0" damping="0.001" frictionloss="0.001"/>
        <geom name="thumb_mesh_1" pos="0.0278284 0 0.0147507" quat="0.608761 0.793353 0 0" type="mesh" mass="0.00635888" mesh="thumb-F1-MIR"/>
        <body name="thumb_L2" pos="0.0278284 0 0.0147507" quat="0.608761 0.793353 0 0" gravcomp="0">
          <joint name="thumb_q2" pos="0 0 0" axis="0 0 1" range="0 2.0944" damping="0.001" frictionloss="0.001"/>
          <geom name="thumb_mesh_2" pos="0.0651867 0.0233402 0.00393483" quat="3.21978e-07 -0.985259 -0.171069 5.59046e-08" type="mesh" mass="0.00645" mesh="thumb-F2"/>
        </body>
      </body>
    </body>
  </worldbody>

  <actuator>
    <position name="index_actuator" joint="index_q1" ctrllimited="true" ctrlrange="0 1.74"/>
    <position name="middle_actuator" joint="middle_q1" ctrllimited="true" ctrlrange="0 1.74"/>
    <position name="ring_actuator" joint="ring_q1" ctrllimited="true" ctrlrange="0 1.74"/>
    <position name="pinky_actuator" joint="pinky_q1" ctrllimited="true" ctrlrange="0 1.74"/>
    <position name="thumbrotator_actuator" joint="thumb_q1" ctrllimited="true" ctrlrange="-1.8 0"/>
    <position name="thumbflexor_actuator" joint="thumb_q2" ctrllimited="true" ctrlrange="0 1.5"/>
  </actuator>
  
  <equality>
      <joint name="index_link" joint1="index_q2" joint2="index_q1" polycoef="0.72349796 1.05851325 0 0" solimp=".95 .98 .01" solref=".02 0.95"/>
      <joint name="middle_link" joint1="middle_q2" joint2="middle_q1" polycoef="0.72349796 1.05851325  0 0 0" solimp=".95 .98 .01" solref=".02 0.95"/>
      <joint name="ring_link" joint1="ring_q2" joint2="ring_q1" polycoef="0.72349796 1.05851325 0 0 0" solimp=".95 .98 .01" solref=".02 0.95"/>
      <joint name="pinky_link" joint1="pinky_q2" joint2="pinky_q1" polycoef="0.72349796 1.05851325 0 0 0" solimp=".95 .98 .01" solref=".02 0.95"/>
      <weld body1="wand" body2="hand" solimp=".99 .995 .001" solref=".005 1"/>
  </equality>

</mujoco>
