<mujoco model="h1">
  <compiler angle="radian" meshdir="assets" autolimits="true"/>

  <statistic meansize="0.05"/>

  <default>
    <default class="h1">
      <joint damping="1" armature="0.1"/>
      <default class="visual">
        <geom type="mesh" contype="0" conaffinity="0" group="2" material="black"/>
      </default>
      <default class="collision">
        <geom group="3" mass="0" density="0"/>
        <default class="foot">
          <geom type="capsule" size=".014"/>
          <default class="foot1">
            <geom fromto="-.035 0 -0.056 .02 0 -0.045"/>
          </default>
          <default class="foot2">
            <geom fromto=".02 0 -0.045 .115 0 -0.056"/>
          </default>
          <default class="foot3">
            <geom fromto=".14 -.03 -0.056 .14 .03 -0.056"/>
          </default>
        </default>
      </default>
      <site size="0.001" rgba="0.5 0.5 0.5 0.3" group="4"/>
    </default>

    <default class="ability_hand">
      <!--Visual Meshes-->
      <default class="visual_ah">
        <geom mass="0" type="mesh" contype="0" conaffinity="0" group="1" rgba="0.1 0.1 0.1 1"/>

        <default class="wrist_visual">
          <geom mesh="wrist_mesh" rgba ="0 0 0 1"/>
        </default>

        <default class="palm_visual">
          <geom pos="-0.0240477 0.00378125 0.0323296" quat="0.0442297 0.00061027 -0.999021 -2.70192e-05" mesh="palm_mesh"/>
        </default>

        <default class="finger_visual">
          <geom rgba="0.15 0.15 0.15 1"/>

          <default class="finger_prox_vis">
            <geom pos="0.0384727 0.0032577 0" quat="0.999108 0 0 0.0422244" mesh="finger_prox_mesh"/>
          </default>

          <default class="finger_int_dist_vis">
            <geom pos="0.0091241 0 0" mesh="finger_int_dist_mesh"/>
          </default>

          <default class="pinky_int_dist_vis">
            <geom pos="0.0091241 0 0" mesh="pinky_int_dist_mesh"/>
          </default>

          <default class="thumb_metacarp_vis">
            <geom pos="0.0278284 0 0.0147507" quat="0.608761 0.793353 0 0" mesh="thumb_metacarp_mesh"/>
          </default>

          <default class="thumb_prox_dist_vis">
            <geom  pos="0.0651867 0.0233402 0.00393483" quat="3.21978e-07 -0.985259 -0.171069 5.59046e-08" mesh="thumb_prox_dist_mesh"/>
          </default>
        </default>
      </default>
      <!--/visual-->

      <!--Collisions Primitives-->
      <default class="collisions_ah">
        <geom type="mesh" rgba="1 1 1 1" group="3" solref=".01 .99" solimp=".95 .99 .002"/>
        <default class="wrist_collision">
          <geom type="cylinder" pos="0 0 0.0025" size="0.018 0.0025" mass="0.01591"/>
        </default>

        <default class="palm_collision">
          <geom pos="-0.0240477 0.00378125 0.0323296" quat="0.0442297 0.00061027 -0.999021 -2.70192e-05" mesh="palm_hull_mesh" solref=".01 1" solimp=".98 .995 .0005" mass="0.3592"/>
        </default>

        <default class="proximal_collision">
          <geom pos="0.0384727 0.0032577 0" quat="0.999108 0 0 0.0422244" mesh="finger_prox_hull_mesh" mass="0.00636"/>
        </default>

        <default class="int_dist_collision">
          <geom pos="0.0091241 0 0" mesh="finger_int_dist_hull_mesh" mass="0.006"/>
        </default>

        <default class="pinky_int_dist_collision">
          <geom pos="0.0091241 0 0" mesh="pinky_int_dist_hull_mesh" mass="0.006"/>
        </default>

        <default class="thumb_metacarp_collision">
          <geom pos="0.0278284 0 0.0147507" quat="0.608761 0.793353 0 0" mesh="thumb_metacarp_hull_mesh" mass="0.002"/>
        </default>

        <default class="thumb_prox_collision">
          <geom  pos="0.0651867 0.0233402 0.00393483" quat="3.21978e-07 -0.985259 -0.171069 5.59046e-08" mesh="thumb_prox_dist_hull_mesh" mass="0.06"/>
        </default>
      </default>

      <!--Joints-->
      <default class="joints">
        <joint type="hinge" pos="0 0 0" axis="0 0 1" damping="0.01" frictionloss="0.1"/>
        <position kp="1" kv="0" ctrllimited="true"/>

        <default class="finger_mcp_joint">
          <joint range="0 1.74"/>
          <position ctrlrange="0 1.74"/>
        </default>

        <default class="finger_pip_joint">
          <joint range="0.766 2.61"/>
          <position ctrlrange="0.766 2.61"/>
        </default>

        <default class="thumb_mcp_joint">
          <joint range="0 1.91"/>
          <position ctrlrange="0 1.91"/>
        </default>

        <default class="thumb_cmc_joint">
          <joint range="-2.09 0"/>
          <position ctrlrange="-2.09 0"/>
        </default>
      </default>

      <!--FSR--> 
      <default class="fsr"> 
        <site type="box" size="0.005 0.003 0.003" rgba="0 0 1 0.3" group="3"/>
        <default class="fsr_0">
          <site pos="0.02936 -0.01697 -0.00435" quat="-0.00000 0.99573 -0.09227 -0.00000"/>
        </default>
        <default class="fsr_1">
          <site size="0.005 0.003 0.0035" pos="0.02961 -0.01394 0.00000" quat="-0.70237 0.70237 -0.08170 0.08170"/>
        </default>
        <default class="fsr_2">
          <site pos="0.02936 -0.01697 0.00435" quat="0.99573 -0.00000 0.00000 -0.09227"/>
        </default>
        <default class="fsr_3">
          <site size="0.005 0.003 0.0035" pos="0.01472 -0.01100 -0.00435" quat="-0.00000 0.95953 -0.28160 -0.00000"/>
        </default>
        <default class="fsr_4">
          <site size="0.005 0.003 0.0035" pos="0.01472 -0.01099 0.00435" quat="0.95938 -0.00000 0.00000 -0.28211"/>
        </default>
        <default class="fsr_5">
          <site size="0.005 0.003 0.0025" pos="0.03704 -0.01785 0.00000" quat="-0.16551 0.68746 0.16551 0.68746"/>
        </default>
        <default class="t_fsr_0">
          <site size="0.005 0.003 0.006" pos="0.04747 0.01988 -0.001239" quat="-0.40374 0.89107 0.18885 -0.08557"/>
        </default>
        <default class="t_fsr_1">
          <site size="0.005 0.003 0.0065" pos="0.04721 0.02124 0.006439" quat="0.77611 -0.59553 -0.12621 0.16449"/>
        </default>
        <default class="t_fsr_2">
          <site  size="0.005 0.003 0.004" pos="0.04896 0.01654 0.01241" quat="0.96520 -0.15936 -0.03377 0.20456"/>
        </default>
        <default class="t_fsr_3">
          <site size="0.005 0.003 0.0065" pos="0.03739 0.01536 -0.001289" quat="-0.40374 0.89107 0.18885 -0.08557"/>
        </default>
        <default class="t_fsr_4">
          <site size="0.005 0.003 0.004" pos="0.03888 0.01200 0.01244" quat="0.96520 -0.15936 -0.03377 0.20456"/>
        </default>
        <default class="t_fsr_5">
          <site size="0.005 0.003 0.007" pos="0.05591 0.02160 0.00558" quat="0.76035 -0.61095 0.20037 -0.09196"/>
        </default>
      </default>  
    </default>
  </default>

  <asset>
    <material name="black" rgba="0.1 0.1 0.1 1"/>
    <material name="white" rgba="1 1 1 1"/>

    <mesh file="pelvis.stl"/>
    <mesh file="left_hip_yaw_link.stl"/>
    <mesh file="left_hip_roll_link.stl"/>
    <mesh file="left_hip_pitch_link.stl"/>
    <mesh file="left_knee_link.stl"/>
    <mesh file="left_ankle_link.stl"/>
    <mesh file="right_hip_yaw_link.stl"/>
    <mesh file="right_hip_roll_link.stl"/>
    <mesh file="right_hip_pitch_link.stl"/>
    <mesh file="right_knee_link.stl"/>
    <mesh file="right_ankle_link.stl"/>
    <mesh file="torso_link.stl"/>
    <mesh file="left_shoulder_pitch_link.stl"/>
    <mesh file="left_shoulder_roll_link.stl"/>
    <mesh file="left_shoulder_yaw_link.stl"/>
    <mesh file="left_elbow_link.stl"/>
    <mesh file="right_shoulder_pitch_link.stl"/>
    <mesh file="right_shoulder_roll_link.stl"/>
    <mesh file="right_shoulder_yaw_link.stl"/>
    <mesh file="right_elbow_link.stl"/>
    <mesh file="logo_link.stl"/>
    <mesh name="wrist_mesh" file="wristmesh.STL"/>
    <mesh name="palm_mesh" file="FB_palm_ref_MIR.STL"/>
    <mesh name="palm_hull_mesh" file="palm_hull_mir.STL"/>
    <mesh name="finger_prox_mesh" file="idx-F1.STL"/>
    <mesh name="finger_prox_hull_mesh" file="idx-F1-hull.STL"/>
    <mesh name="finger_int_dist_mesh" file="idx-F2-Lg.STL"/>
    <mesh name="finger_int_dist_hull_mesh" file="idx-F2-Lg-hull.STL"/>
    <mesh name="pinky_int_dist_mesh" file="idx-F2.STL"/>
    <mesh name="pinky_int_dist_hull_mesh" file="idx-F2-hull.STL"/>
    <mesh name="thumb_metacarp_mesh" file="thumb-F1-MIR.STL"/>
    <mesh name="thumb_metacarp_hull_mesh" file="thumb-F1-MIR-hull.STL"/>
    <mesh name="thumb_prox_dist_mesh" file="thumb-F2.STL"/>
    <mesh name="thumb_prox_dist_hull_mesh" file="thumb-F2-hull.STL"/>
  </asset>

  <worldbody>
    <light mode="targetbodycom" target="torso_link" pos="2 0 2.5"/>
    <body name="pelvis" pos="0 0 1.06" childclass="h1">
      <inertial pos="-0.0002 4e-05 -0.04522" quat="0.498303 0.499454 -0.500496 0.501741" mass="5.39"
        diaginertia="0.0490211 0.0445821 0.00824619"/>
      <freejoint/>
      <geom class="visual" mesh="pelvis"/>
      <body name="left_hip_yaw_link" pos="0 0.0875 -0.1742">
        <inertial pos="-0.04923 0.0001 0.0072" quat="0.69699 0.219193 0.233287 0.641667" mass="2.244"
          diaginertia="0.00304494 0.00296885 0.00189201"/>
        <joint name="left_hip_yaw" axis="0 0 1" range="-0.43 0.43"/>
        <geom class="visual" mesh="left_hip_yaw_link"/>
        <geom size="0.06 0.035" pos="-0.067 0 0" quat="0.707123 0 0.70709 0" type="cylinder" class="collision"/>
        <body name="left_hip_roll_link" pos="0.039468 0 0">
          <inertial pos="-0.0058 -0.00319 -9e-05" quat="0.0438242 0.70721 -0.0729075 0.701867" mass="2.232"
            diaginertia="0.00243264 0.00225325 0.00205492"/>
          <joint name="left_hip_roll" axis="1 0 0" range="-0.43 0.43"/>
          <geom class="visual" mesh="left_hip_roll_link"/>
          <geom class="collision" type="cylinder" size="0.05 0.03" quat="1 1 0 0" pos="0 -0.02 0"/>
          <body name="left_hip_pitch_link" pos="0 0.11536 0">
            <inertial pos="0.00746 -0.02346 -0.08193" quat="0.979828 0.0513522 -0.0169854 -0.192382" mass="4.152"
              diaginertia="0.0829503 0.0821457 0.00510909"/>
            <joint name="left_hip_pitch" axis="0 1 0" range="-1.57 1.57"/>
            <geom class="visual" mesh="left_hip_pitch_link"/>
            <geom class="collision" type="capsule" size="0.03" fromto="0.02 0 -0.4 -0.02 0 0.02"/>
            <geom class="collision" type="capsule" size="0.03" fromto="0.02 0 -0.4 0.02 0 0.02"/>
            <geom class="collision" type="cylinder" size="0.05 0.02" quat="1 1 0 0" pos="0 -0.07 0"/>
            <body name="left_knee_link" pos="0 0 -0.4">
              <inertial pos="-0.00136 -0.00512 -0.1384" quat="0.626132 -0.034227 -0.0416277 0.777852" mass="1.721"
                diaginertia="0.0125237 0.0123104 0.0019428"/>
              <joint name="left_knee" axis="0 1 0" range="-0.26 2.05"/>
              <geom class="visual" mesh="left_knee_link"/>
              <geom class="collision" type="capsule" size="0.025" fromto="0.02 0 -0.4 0.02 0 0"/>
              <geom class="collision" type="sphere" size="0.05" pos="0 0 -0.115"/>
              <body name="left_ankle_link" pos="0 0 -0.4">
                <inertial pos="0.06722 0.00015 -0.04497" quat="0.489101 0.503197 0.565782 0.432972" mass="0.446"
                  diaginertia="0.00220848 0.00218961 0.000214202"/>
                <joint name="left_ankle" axis="0 1 0" range="-0.87 0.52"/>
                <geom class="visual" mesh="left_ankle_link"/>
                <geom class="foot1"/>
                <geom class="foot2"/>
                <geom class="foot3"/>
              </body>
            </body>
          </body>
        </body>
      </body>
      <body name="right_hip_yaw_link" pos="0 -0.0875 -0.1742">
        <inertial pos="-0.04923 -0.0001 0.0072" quat="0.641667 0.233287 0.219193 0.69699" mass="2.244"
          diaginertia="0.00304494 0.00296885 0.00189201"/>
        <joint name="right_hip_yaw" axis="0 0 1" range="-0.43 0.43"/>
        <geom class="visual" mesh="right_hip_yaw_link"/>
        <geom size="0.06 0.035" pos="-0.067 0 0" quat="0.707123 0 0.70709 0" type="cylinder" class="collision"/>
        <body name="right_hip_roll_link" pos="0.039468 0 0">
          <inertial pos="-0.0058 0.00319 -9e-05" quat="-0.0438242 0.70721 0.0729075 0.701867" mass="2.232"
            diaginertia="0.00243264 0.00225325 0.00205492"/>
          <joint name="right_hip_roll" axis="1 0 0" range="-0.43 0.43"/>
          <geom class="visual" mesh="right_hip_roll_link"/>
          <geom class="collision" type="cylinder" size="0.05 0.03" quat="1 1 0 0" pos="0 0.02 0"/>
          <body name="right_hip_pitch_link" pos="0 -0.11536 0">
            <inertial pos="0.00746 0.02346 -0.08193" quat="0.979828 -0.0513522 -0.0169854 0.192382" mass="4.152"
              diaginertia="0.0829503 0.0821457 0.00510909"/>
            <joint name="right_hip_pitch" axis="0 1 0" range="-1.57 1.57"/>
            <geom class="visual" mesh="right_hip_pitch_link"/>
            <geom class="collision" type="capsule" size="0.03" fromto="0.02 0 -0.4 -0.02 0 0.02"/>
            <geom class="collision" type="capsule" size="0.03" fromto="0.02 0 -0.4 0.02 0 0.02"/>
            <geom class="collision" type="cylinder" size="0.05 0.02" quat="1 1 0 0" pos="0 0.07 0"/>
            <body name="right_knee_link" pos="0 0 -0.4">
              <inertial pos="-0.00136 0.00512 -0.1384" quat="0.777852 -0.0416277 -0.034227 0.626132" mass="1.721"
                diaginertia="0.0125237 0.0123104 0.0019428"/>
              <joint name="right_knee" axis="0 1 0" range="-0.26 2.05"/>
              <geom class="visual" mesh="right_knee_link"/>
              <geom class="collision" type="capsule" size="0.025" fromto="0.02 0 -0.4 0.02 0 0"/>
              <geom class="collision" type="sphere" size="0.05" pos="0 0 -0.115"/>
              <body name="right_ankle_link" pos="0 0 -0.4">
                <inertial pos="0.06722 -0.00015 -0.04497" quat="0.432972 0.565782 0.503197 0.489101" mass="0.446"
                  diaginertia="0.00220848 0.00218961 0.000214202"/>
                <joint name="right_ankle" axis="0 1 0" range="-0.87 0.52"/>
                <geom class="visual" mesh="right_ankle_link"/>
                <geom class="foot1"/>
                <geom class="foot2"/>
                <geom class="foot3"/>
              </body>
            </body>
          </body>
        </body>
      </body>
      <body name="torso_link">
        <inertial pos="0.000489 0.002797 0.20484" quat="0.999989 -0.00130808 -0.00282289 -0.00349105" mass="17.789"
          diaginertia="0.487315 0.409628 0.127837"/>
        <joint name="torso" axis="0 0 1" range="-2.35 2.35"/>
        <geom class="visual" mesh="torso_link"/>
        <geom class="visual" material="white" mesh="logo_link"/>
        <geom name="head" class="collision" type="capsule" size="0.06" fromto="0.05 0 0.68 0.05 0 0.6"/>
        <geom name="helmet" class="collision" type="sphere" size="0.073" pos="0.045 0 0.68"/>
        <geom name="torso" class="collision" type="box" size="0.07 0.1 0.22" pos="0 0 0.25"/>
        <geom name="hip" class="collision" type="capsule" size="0.05" fromto="0 -0.1 -0.05 0 0.1 -0.05"/>
        <site name="imu" pos="-0.04452 -0.01891 0.27756"/>
        <body name="left_shoulder_pitch_link" pos="0.0055 0.15535 0.42999" quat="0.976296 0.216438 0 0">
          <inertial pos="0.005045 0.053657 -0.015715" quat="0.814858 0.579236 -0.0201072 -0.00936488" mass="1.033"
            diaginertia="0.00129936 0.000987113 0.000858198"/>
          <joint name="left_shoulder_pitch" axis="0 1 0" range="-2.87 2.87"/>
          <geom class="visual" mesh="left_shoulder_pitch_link"/>
          <body name="left_shoulder_roll_link" pos="-0.0055 0.0565 -0.0165" quat="0.976296 -0.216438 0 0">
            <inertial pos="0.000679 0.00115 -0.094076" quat="0.732491 0.00917179 0.0766656 0.676384" mass="0.793"
              diaginertia="0.00170388 0.00158256 0.00100336"/>
            <joint name="left_shoulder_roll" axis="1 0 0" range="-0.34 3.11"/>
            <geom class="visual" mesh="left_shoulder_roll_link"/>
            <geom name="left_shoulder" class="collision" type="capsule" size="0.04" fromto="0 0.01 0.008 0 -0.07 -0.02"/>
            <body name="left_shoulder_yaw_link" pos="0 0 -0.1343">
              <inertial pos="0.01365 0.002767 -0.16266" quat="0.703042 -0.0331229 -0.0473362 0.708798" mass="0.839"
                diaginertia="0.00408038 0.00370367 0.000622687"/>
              <joint name="left_shoulder_yaw" axis="0 0 1" range="-1.3 4.45"/>
              <geom class="visual" mesh="left_shoulder_yaw_link"/>
              <geom class="collision" type="capsule" size="0.03" fromto="0 0 0.15 0 0 -0.2"/>
              <body name="left_elbow_link" pos="0.0185 0 -0.198">
                <inertial pos="0.15908 -0.000144 -0.015776" quat="0.0765232 0.720327 0.0853116 0.684102" mass="0.669"
                  diaginertia="0.00601829 0.00600579 0.000408305"/>
                <joint name="left_elbow" axis="0 1 0" range="-1.25 2.61"/>
                <geom class="visual" mesh="left_elbow_link"/>
                <geom class="collision" type="capsule" size="0.025" fromto="0 0 0 0.28 0 -0.015"/>
                <geom class="collision" type="sphere" size="0.033" pos="0.28 0 -0.015"/>
              </body>
            </body>
          </body>
        </body>
        <body name="right_shoulder_pitch_link" pos="0.0055 -0.15535 0.42999" quat="0.976296 -0.216438 0 0">
          <inertial pos="0.005045 -0.053657 -0.015715" quat="0.579236 0.814858 0.00936488 0.0201072" mass="1.033"
            diaginertia="0.00129936 0.000987113 0.000858198"/>
          <joint name="right_shoulder_pitch" axis="0 1 0" range="-2.87 2.87"/>
          <geom class="visual" mesh="right_shoulder_pitch_link"/>
          <body name="right_shoulder_roll_link" pos="-0.0055 -0.0565 -0.0165" quat="0.976296 0.216438 0 0">
            <inertial pos="0.000679 -0.00115 -0.094076" quat="0.676384 0.0766656 0.00917179 0.732491" mass="0.793"
              diaginertia="0.00170388 0.00158256 0.00100336"/>
            <joint name="right_shoulder_roll" axis="1 0 0" range="-3.11 0.34"/>
            <geom class="visual" mesh="right_shoulder_roll_link"/>
            <geom name="right_shoulder" class="collision" type="capsule" size="0.04" fromto="0 -0.01 0.008 0 0.07 -0.02"/>
            <body name="right_shoulder_yaw_link" pos="0 0 -0.1343">
              <inertial pos="0.01365 -0.002767 -0.16266" quat="0.708798 -0.0473362 -0.0331229 0.703042" mass="0.839"
                diaginertia="0.00408038 0.00370367 0.000622687"/>
              <joint name="right_shoulder_yaw" axis="0 0 1" range="-4.45 1.3"/>
              <geom class="visual" mesh="right_shoulder_yaw_link"/>
              <geom class="collision" type="capsule" size="0.03" fromto="0 0 0.15 0 0 -0.2"/>
              <body name="right_elbow_link" pos="0.0185 0 -0.198">
                <inertial pos="0.15908 0.000144 -0.015776" quat="-0.0765232 0.720327 -0.0853116 0.684102" mass="0.669"
                  diaginertia="0.00601829 0.00600579 0.000408305"/>
                <joint name="right_elbow" axis="0 1 0" range="-1.25 2.61"/>
                <geom class="visual" mesh="right_elbow_link"/>
                <geom class="collision" type="capsule" size="0.025" fromto="0 0 0 0.28 0 -0.015"/>
                <body name="ability_hand" pos="0.28 0 -0.015" euler="0 1.57 0" childclass="ability_hand">
                  <geom class="wrist_visual"/>
                  <geom name="wrist_coll" class="wrist_collision"/>
                  <geom class="palm_visual"/>
                  <geom name="palm_coll" class="palm_collision"/>
                  <!--Index-->
                  <body name="index_prox" pos="-0.0279216 -0.00927034 0.0958706" quat="0.685906 0.0469401 -0.714459 -0.129917">
                      <joint class="finger_mcp_joint" name="index_mcp"/>
                      <geom name="idx_prox_coll" class="proximal_collision"/>
                      <geom class="finger_prox_vis"/>
                      <body name="index_int_dist" pos="0.0384727 0.0032577 0" quat="0.999108 0 0 0.0422244">
                        <site class="fsr_0" name="fsr0"/>
                        <site class="fsr_1" name="fsr1"/>
                        <site class="fsr_2" name="fsr2"/>
                        <site class="fsr_3" name="fsr3"/>
                        <site class="fsr_4" name="fsr4"/>
                        <site class="fsr_5" name="fsr5"/>
                        <joint class="finger_pip_joint" name="index_pip"/>
                        <geom class="int_dist_collision"/>
                        <geom class="finger_int_dist_vis"/>
                      </body>
                  </body>
                  <!--Middle-->
                  <body name="middle_prox" pos="-0.00841718 -0.0115172 0.0990634" quat="0.704562 0.0715738 -0.698395 -0.103508">
                      <joint class="finger_mcp_joint" name="middle_mcp"/>
                      <geom class="proximal_collision"/>
                      <geom class="finger_prox_vis"/>
                      <body name="middle_int_dist" pos="0.0384727 0.0032577 0" quat="0.999108 0 0 0.0422244">
                        <joint class="finger_pip_joint" name="middle_pip"/>
                        <site class="fsr_0" name="fsr6"/>
                        <site class="fsr_1" name="fsr7"/>
                        <site class="fsr_2" name="fsr8"/>
                        <site class="fsr_3" name="fsr9"/>
                        <site class="fsr_4" name="fsr10"/>
                        <site class="fsr_5" name="fsr11"/>
                        <geom class="int_dist_collision"/>
                        <geom class="finger_int_dist_vis"/>
                      </body>
                  </body>
                  <!--Ring-->
                  <body name="ring_prox" pos="0.0117529 -0.0103946 0.0967038" quat="0.721351 0.0986547 -0.681173 -0.0769649">
                      <joint class="finger_mcp_joint" name="ring_mcp"/>
                      <geom class="proximal_collision"/>
                      <geom class="finger_prox_vis"/>
                      <body name="ring_int_dist" pos="0.0384727 0.0032577 0" quat="0.999108 0 0 0.0422244">
                        <joint class="finger_pip_joint" name="ring_pip"/>
                        <site class="fsr_0" name="fsr12"/>
                        <site class="fsr_1" name="fsr13"/>
                        <site class="fsr_2" name="fsr14"/>
                        <site class="fsr_3" name="fsr15"/>
                        <site class="fsr_4" name="fsr16"/>
                        <site class="fsr_5" name="fsr17"/>
                        <geom class="int_dist_collision"/>
                        <geom class="finger_int_dist_vis"/>
                      </body>
                  </body>
                  <!--Pinky-->
                  <body name="pinky_prox" pos="0.0308633 -0.00716283 0.0907346" quat="0.719226 0.122363 -0.681748 -0.0544096">
                      <joint class="finger_mcp_joint" name="pinky_mcp"/>
                      <geom class="proximal_collision"/>
                      <geom class="finger_prox_vis"/>
                      <body name="pinky_int_dist" pos="0.0384727 0.0032577 0" quat="0.999108 0 0 0.0422244">
                        <joint class="finger_pip_joint" name="pinky_pip"/>
                        <site class="fsr_0" name="fsr18" pos="0.02556 -0.01391 -0.00435" quat="0.00000 0.99797 -0.06376 -0.00000"/>
                        <site class="fsr_1" name="fsr19" pos="0.02517 -0.01110 -0.00000" quat="-0.70527 0.70527 -0.05099 0.05099"/>
                        <site class="fsr_2" name="fsr20" pos="0.02556 -0.01391 0.00435" quat="0.99797 -0.00000 0.00000 -0.06376"/>
                        <site class="fsr_3" name="fsr21" pos="0.01310 -0.00943 -0.00435" quat="-0.00000 0.96544 -0.26063 0.00000"/>
                        <site class="fsr_4" name="fsr22" pos="0.01310 -0.00943 0.00435" quat="0.96544 -0.00000 0.00000 -0.26063"/>
                        <site class="fsr_5" name="fsr23" pos="0.03142 -0.01438 0.00000" quat="-0.14469 0.69214 0.14469 0.69214" size="0.005 0.003 0.00385"/>
                        <geom class="pinky_int_dist_collision"/>
                        <geom class="pinky_int_dist_vis"/>
                      </body>
                  </body>
                  <!--Thumb-->
                  <body name="thumb_metacarp" pos="-0.0240477 0.00378125 0.0323296" quat="-0.0947972 0.0440301 -0.00419696 0.994514">
                    <joint class="thumb_cmc_joint" name="thumb_cmc"/>
                    <geom class="thumb_metacarp_vis"/>
                    <geom class="thumb_metacarp_collision"/>
                    <body name="thumb_mcp" pos="0.0278284 0 0.0147507" quat="0.608761 0.793353 0 0">
                      <joint class="thumb_mcp_joint" name="thumb_mcp"/>
                      <site class="t_fsr_0" name="fsr24"/>
                      <site class="t_fsr_1" name="fsr25"/>
                      <site class="t_fsr_2" name="fsr26"/>
                      <site class="t_fsr_3" name="fsr27"/>
                      <site class="t_fsr_4" name="fsr28"/>
                      <site class="t_fsr_5" name="fsr29"/>
                      <geom class="thumb_prox_collision"/>
                      <geom class="thumb_prox_dist_vis"/>
                    </body>
                  </body>
                </body>

              </body>
            </body>
          </body>
        </body>
      </body>
    </body>
  </worldbody>

  <sensor>
    <touch site="fsr0"/>
    <touch site="fsr1"/>
    <touch site="fsr2"/>
    <touch site="fsr3"/>
    <touch site="fsr4"/>
    <touch site="fsr5"/>
    <touch site="fsr6"/>
    <touch site="fsr7"/>
    <touch site="fsr8"/>
    <touch site="fsr9"/>
    <touch site="fsr10"/>
    <touch site="fsr11"/>
    <touch site="fsr12"/>
    <touch site="fsr13"/>
    <touch site="fsr14"/>
    <touch site="fsr15"/>
    <touch site="fsr16"/>
    <touch site="fsr17"/>
    <touch site="fsr18"/>
    <touch site="fsr19"/>
    <touch site="fsr20"/>
    <touch site="fsr21"/>
    <touch site="fsr22"/>
    <touch site="fsr23"/>
    <touch site="fsr24"/>
    <touch site="fsr25"/>
    <touch site="fsr26"/>
    <touch site="fsr27"/>
    <touch site="fsr28"/>
    <touch site="fsr29"/>
  </sensor>

  <contact>
    <exclude body1="torso_link" body2="left_shoulder_roll_link"/>
    <exclude body1="torso_link" body2="right_shoulder_roll_link"/>
  </contact>

  <actuator>
    <motor class="h1" name="left_hip_yaw" joint="left_hip_yaw" ctrlrange="-200 200"/>
    <motor class="h1" name="left_hip_roll" joint="left_hip_roll" ctrlrange="-200 200"/>
    <motor class="h1" name="left_hip_pitch" joint="left_hip_pitch" ctrlrange="-200 200"/>
    <motor class="h1" name="left_knee" joint="left_knee" ctrlrange="-300 300"/>
    <motor class="h1" name="left_ankle" joint="left_ankle" ctrlrange="-40 40"/>
    <motor class="h1" name="right_hip_yaw" joint="right_hip_yaw" ctrlrange="-200 200"/>
    <motor class="h1" name="right_hip_roll" joint="right_hip_roll" ctrlrange="-200 200"/>
    <motor class="h1" name="right_hip_pitch" joint="right_hip_pitch" ctrlrange="-200 200"/>
    <motor class="h1" name="right_knee" joint="right_knee" ctrlrange="-300 300"/>
    <motor class="h1" name="right_ankle" joint="right_ankle" ctrlrange="-40 40"/>
    <motor class="h1" name="torso" joint="torso" ctrlrange="-200 200"/>
    <motor class="h1" name="left_shoulder_pitch" joint="left_shoulder_pitch" ctrlrange="-40 40"/>
    <motor class="h1" name="left_shoulder_roll" joint="left_shoulder_roll" ctrlrange="-40 40"/>
    <motor class="h1" name="left_shoulder_yaw" joint="left_shoulder_yaw" ctrlrange="-18 18"/>
    <motor class="h1" name="left_elbow" joint="left_elbow" ctrlrange="-18 18"/>
    <motor class="h1" name="right_shoulder_pitch" joint="right_shoulder_pitch" ctrlrange="-40 40"/>
    <motor class="h1" name="right_shoulder_roll" joint="right_shoulder_roll" ctrlrange="-40 40"/>
    <motor class="h1" name="right_shoulder_yaw" joint="right_shoulder_yaw" ctrlrange="-18 18"/>
    <motor class="h1" name="right_elbow" joint="right_elbow" ctrlrange="-18 18"/>
  </actuator>
</mujoco>
