<mujoco model="ability_hand">
  <compiler angle="radian" meshdir="./assets" autolimits="true"/>

  <default>
    <default class="ability_hand">

      <!--Visual Meshes-->
      <default class="visual">
        <geom mass="0" type="mesh" contype="0" conaffinity="0" group="1" rgba="0.1 0.1 0.1 1"/>

        <default class="wrist_visual">
          <geom mesh="wrist_mesh" rgba ="0 0 0 1"/>
        </default>

        <default class="palm_visual">
          <geom pos="0.0240477 0.00378125 0.0323296" quat="0.0442297 0.00061027 0.999021 2.70192e-05" mesh="palm_mesh"/>
        </default>

        <default class="finger_visual">
          <geom rgba="0.15 0.15 0.15 1"/>

          <default class="finger_prox_vis">
            <geom pos="0.0384727 0.0032577 0" quat="0.999108 0 0 0.0422244" mesh="finger_prox_mesh"/>
          </default>

          <default class="finger_int_dist_vis">
            <geom pos="0.0091241 0 0" mesh="finger_int_dist_mesh"/>
          </default>

          <default class="thumb_metacarp_vis">
            <geom pos="0.0278284 0 -0.0147507" quat="-0.608761 0.793353 0 0" mesh="thumb_metacarp_mesh"/>
          </default>

          <default class="thumb_prox_dist_vis">
            <geom pos="0.0651867 0.0233402 -0.00393483" quat="3.21978e-07 0.985259 0.171069 5.59046e-08" mesh="thumb_prox_dist_mesh"/>
          </default>
        </default>
      </default>
      <!--/visual-->

      <!--Collisions Primitives-->
      <default class="collisions">
        <geom rgba="1 1 1 0.2" group="3" solref=".01 .99" solimp=".95 .99 .002"/>
        <default class="wrist_collision">
          <geom type="cylinder" pos="0 0 0.0025" size="0.018 0.0025" mass="0.01591"/>
        </default>

        <default class="palm_collision">
          <geom type="ellipsoid" quat="0.996 0.155 0 0" pos="0 0 0.05" size="0.037 0.012 0.052" solref=".01 1" solimp=".98 .995 .0005" mass="0.3592"/>
        </default>

        <default class="proximal_collision">
          <geom type="capsule" quat="0.707 0 0.707 0" pos="0.015 0.002 0" size="0.007 0.017" mass="0.00636"/>
        </default>

        <default class="int_dist_collision">
          <geom type="capsule" pos="0.018 -0.012 0" euler="1.5708 -2.0943951023931953 0" size="0.007 0.017" mass="0.006"/>
        </default>

        <default class="thumb_metacarp_collision">
          <geom type="capsule" pos="0.013 0 -0.005" quat="-0.9238795325112866 0.1 0.6526834323650898 0" size="0.010 0.013" mass="0.002"/>
        </default>

        <default class="thumb_prox_collision">
          <geom type="capsule" pos="0.027 0.01 -0.005" euler="-1.6708 1.2 0" size="0.010 0.027" mass="0.06"/>
        </default>
      </default>

      <!--Joints-->
      <default class="joints">
        <joint type="hinge" pos="0 0 0" axis="0 0 1" damping="0.01" frictionloss="0.1"/>
        <position kp="1" kv="0" ctrllimited="true"/>

        <default class="finger_mcp_joint">
          <joint range="0 1.74"/>
          <position ctrlrange="0 1.74"/>
        </default>

        <default class="finger_pip_joint">
          <joint range="0.766 2.61"/>
          <position ctrlrange="0.766 2.61"/>
        </default>

        <default class="thumb_mcp_joint">
          <joint range="0 1.91"/>
          <position ctrlrange="0 1.91"/>
        </default>

        <default class="thumb_cmc_joint">
          <joint range="-2.09 0"/>
          <position ctrlrange="-2.09 0"/>
        </default>

      </default>
    </default>
  </default>

  <asset>
    <mesh name="wrist_mesh" file="wristmesh.STL"/>
    <mesh name="palm_mesh" file="FB_palm_ref.STL"/>
    <mesh name="finger_prox_mesh" file="idx-F1.STL"/>
    <mesh name="finger_int_dist_mesh" file="idx-F2-Lg.STL"/>
    <mesh name="thumb_metacarp_mesh" file="thumb-F1.STL"/>
    <mesh name="thumb_prox_dist_mesh" file="thumb-F2.STL"/>
  </asset>

  <worldbody>
    <body name="ability_hand" pos="0 0 0.01" childclass="ability_hand">
      <joint type="free" name="base joint"/>
      <geom class="wrist_visual"/>
      <geom class="wrist_collision"/>
      <geom class="palm_visual"/>
      <geom class="palm_collision"/>
      <!--Index-->
      <body name="index_prox" pos="0.0279216 -0.00927034 0.0958706" quat="-0.714459 -0.129917 0.685906 0.0469401">
          <joint class="finger_mcp_joint" name="index_mcp"/>
          <geom class="proximal_collision"/>
          <geom class="finger_prox_vis"/>
          <body name="index_int_dist" pos="0.0384727 0.0032577 0" quat="0.999108 0 0 0.0422244">
            <joint class="finger_pip_joint" name="index_pip"/>
            <geom class="int_dist_collision"/>
            <geom class="finger_int_dist_vis"/>
          </body>
      </body>
      <!--Middle-->
      <body name="middle_prox" pos="0.00841718 -0.0115172 0.0990634" quat="-0.698395 -0.103508 0.704562 0.0715738">
          <joint class="finger_mcp_joint" name="middle_mcp"/>
          <geom class="proximal_collision"/>
          <geom class="finger_prox_vis"/>
          <body name="middle_int_dist" pos="0.0384727 0.0032577 0" quat="0.999108 0 0 0.0422244">
            <joint class="finger_pip_joint" name="middle_pip"/>
            <geom class="int_dist_collision"/>
            <geom class="finger_int_dist_vis"/>
          </body>
      </body>
      <!--Ring-->
      <body name="ring_prox" pos="-0.0117529 -0.0103946 0.0967038" quat="-0.681173 -0.0769649 0.721351 0.0986547">
          <joint class="finger_mcp_joint" name="ring_mcp"/>
          <geom class="proximal_collision"/>
          <geom class="finger_prox_vis"/>
          <body name="ring_int_dist" pos="0.0384727 0.0032577 0" quat="0.999108 0 0 0.0422244">
            <joint class="finger_pip_joint" name="ring_pip"/>
            <geom class="int_dist_collision"/>
            <geom class="finger_int_dist_vis"/>
          </body>
      </body>
      <!--Pinky-->
      <body name="pinky_prox" pos="-0.0308633 -0.00716283 0.0907346" quat="-0.681748 -0.0544096 0.719226 0.122363" >
          <joint class="finger_mcp_joint" name="pinky_mcp"/>
          <geom class="proximal_collision"/>
          <geom class="finger_prox_vis"/>
          <body name="pinky_int_dist" pos="0.0384727 0.0032577 0" quat="0.999108 0 0 0.0422244">
            <joint class="finger_pip_joint" name="pinky_pip"/>
            <geom class="int_dist_collision"/>
            <geom class="finger_int_dist_vis"/>
          </body>
      </body>
      <!--Thumb-->
      <body name="thumb_metacarp" pos="0.0240477 0.00378125 0.0323296" quat="-0.00419696 0.994514 -0.0947972 0.0440301">
        <joint class="thumb_cmc_joint" name="thumb_cmc"/>
        <geom class="thumb_metacarp_vis"/>
        <geom class="thumb_metacarp_collision"/>
        <body name="thumb_mcp" pos="0.0278284 0 -0.0147507" quat="-0.608761 0.793353 0 0">
          <joint class="thumb_mcp_joint" name="thumb_mcp"/>
          <geom class="thumb_prox_collision"/>
          <geom class="thumb_prox_dist_vis"/>
        </body>
      </body>
    </body>
  </worldbody>

  <!--Actuators-->
  <actuator>
    <position class="finger_mcp_joint" name="index_mcp_actuator" joint="index_mcp"/>
    <position class="finger_pip_joint" name="_index_pip_actuator" joint="index_pip"/>
    <position class="finger_mcp_joint" name="middle_mcp_actuator" joint="middle_mcp"/>
    <position class="finger_pip_joint" name="_middle_pip_actuator" joint="middle_pip"/>
    <position class="finger_mcp_joint" name="ring_mcp_actuator" joint="ring_mcp"/>
    <position class="finger_pip_joint" name="_ring_pip_actuator" joint="ring_pip"/>
    <position class="finger_mcp_joint" name="pinky_mcp_actuator" joint="pinky_mcp"/>
    <position class="finger_pip_joint" name="_pinky_pip_actuator" joint="pinky_pip"/>
    <position class="thumb_mcp_joint" name="thumb_flexor_actuator" joint="thumb_mcp"/>
    <position class="thumb_cmc_joint" name="thumb_rotator_actuator" joint="thumb_cmc"/>
  </actuator>

</mujoco>
